Workbook
Name LISTA_TIPOS_VEHICULO: DATOS!$W$2:INDEX(DATOS!$W:$W,COUNTA(DATOS!$W:$W))

Sheet VEHICULOS
A1: POLICÍA NACIONAL DE ECUADOR
A2: DIRECCIÓN NACIONAL DE CONTROL DE TRÁNSITO Y SEGURIDAD VIAL
A3: CENTRO DE RETENCIÓN VEHICULAR "PORTOVIEJO TRES MARIAS"
B5: INGRESO DEL VEHICULO | V5: SALIDA DE VEHICULO | AM5: ALCOHOCHECK | AO5: INVESTIGACIÓN
A6: ORD. | B6: SUBZONA | C6: CENTRO DE RETENCION VEHICULAR | D6: FECHA DE INGRESO | E6: NÚMERO DE FORMULARIO DE INGRESO VEHICULAR | F6: PLACA | G6: MARCA | H6: TIPO | I6: MODELO | J6: COLOR | K6: AÑO DE FABRICACIÓN | L6: NÚMERO DE CHASIS | M6: NÚMERO DE MOTOR | N6: NÚMERO DE PARTE | O6: PARTE ELABORADO POR | P6: NOMBRE PROPIETARIO/RESPONSABLE DEL VEHICULO | Q6: SITUACIÓN LEGAL (Infracción tránsito) | R6: AUTORIDAD QUE CONOCE (Juzgado Y/O fiscalia que avocó conocimiento) | S6: PLACA-GRUA | T6: NOMBRES CONDUCTOR GRUA | U6: NOMBRE SERVIDOR POLICIAL QUE RECIBE LA CUSTODIA DEL VEHÍCULO | V6: FECHA EGRESO | W6: ORDEN DE LIBERTAD EMITIDA AUTORIDAD COMPETENTE | X6: NOMBRE DEL SEÑOR JEFE QUE EMITE LIBERTAD | Y6: NOMBRES DE PERSONA A QUIEN SE ENTREGA | Z6: NÚMERO DE CEDULA | AA6: NÚMERO DE ORDEN DE PAGO (GARAGE) | AB6: TIPO DE TYRAMITE / PROCESO | AC6: DIAS DE PERMANENCIA | AD6: VALOR TARIFARIO DIARIO | AE6: VALOR CANCELADO POR PARQUEO | AF6: No DE ORDEN DE PAGO | AG6: FECHA DE PAGO EN LA ENTIDA FINANCIERA | AH6: No DE COMPROBANTE DE PAGO DE LA ENTIDAD FINANCIERA | AI6: INSTITUCION FINANCIERA (BANCO, COOPERATIVA, ETC) | AJ6: NOMBRE DE LA INSTITUCIÓN FINANCIERA | AK6: NÚMERO DE FORMULARIO DE EGRESO VEHICULAR | AL6: NOMBRE SERVIDOR POLICIAL QUE ENTREGA EL VEHÍCULO (CUSTODIO) | AM6: NÚMERO DE ORDEN DE PAGO POR ALCOHOCHECK | AN6: VALOR CANCELADO POR ALCOHOCHEK | AO6: PERICIAS REALIZADAS | AP6: NOMBRE DEL PERITO | AQ6: FECHA DE PAGO EN LA ENTIDAD FINANCIERA | AR6: NRO. DE COMPROBANTE DE PAGO DE LA ENTIDAD FINANCIERA | AS6: INSTITUCIÓN FINANCIERA (BANCO-COOPERATIVA)
A7: 1 | B7: SANTO DOMINGO | C7: CONTROL 120 | D7: 45904 | E7: 2018 | F7: PPM0426 | G7: SUZUKI | I7: FORSA 1.0L T/M | J7: AZUL | K7: 1995 | L7: SF3105A11578 | M7: G10445928 | N7: 2025090406533790718 | O7: SGOS. TOAQUIZA MARCO | P7: MALES AULLA GERARDO NICOLAS | Q7: ACCIDENTE DE TRANSITO | R7: FISCALIA | S7: N/A | T7: N/A | U7: SGOS. CHASIPANTA XAVIER | AC7: =(V7-D7)+1 -> -45903 | AD7: =IF(AB7="SERVICIO DE GARAJE LIVIANOS (HASTA 3,5 TN A EXCEPCIÓN DE MOTOCICLETAS) (DIARIOS)",3,IF(AB7="SERVICIO DE GARAJE PESADOS (DE 3,51 TN HASTA 12 TN) (DIARIOS)",9,IF(AB7="SERVICIO DE GARAJE (CENTROS DE RETENCIÓN) MOTOCICLETA",1,IF(AB7="SERVICIO DE GARAJE EXTRA PESADOS (MÁS DE 12 TN) (DIARIOS)",15,0)))) -> 0 | AE7: =IFERROR(AD7*AC7,0) -> 0 | AF7: =AA7 -> 0 | AJ7: =IF(AI7="","",AI7) | AK7: =IF(E7="","",E7) -> 2018 | AM7: N/A | AN7: N/A | AQ7: =AG7 -> 0 | AR7: =AH7 -> 0 | AS7: =AJ7
A8: 31 | B8: SANTO DOMINGO | C8: CONTROL 120 | D8: 45998 | E8: 2031 | F8: PQF0838 | G8: FORD | H8: CISTERNA | I8: B1518TURBO 184HP | J8: BLANCO | K8: 2022 | L8: 9BFYTARB1RD879646 | M8: 5513 | N8: ´202512071018484501 | O8: CBOP. ABATA SANTIAGO | P8: ONTANEDA YEPEZ JORGE ANIBAL | Q8: ACCIDENTE DE TRANSITO | R8: FISCALIA | U8: SGOS. CHASIPANTA XAVIER | V8: 46030 | W8: OFICIO No. FPSD-FEAT1-0258-2026-000018-O | X8: MAYOR. SUAREZ JACOME JUAN CARLOS | Y8: =P8 -> ONTANEDA YEPEZ JORGE ANIBAL | Z8: 1711325496 | AA8: 95747679 | AB8: SERVICIO DE GARAJE PESADOS (DE 3,51 TN HASTA 12 TN) (DIARIOS) | AC8: =(V8-D8)+1 -> 33 | AD8: =IF(AB8="SERVICIO DE GARAJE LIVIANOS (HASTA 3,5 TN A EXCEPCIÓN DE MOTOCICLETAS) (DIARIOS)",3,IF(AB8="SERVICIO DE GARAJE PESADOS (DE 3,51 TN HASTA 12 TN) (DIARIOS)",9,IF(AB8="SERVICIO DE GARAJE (CENTROS DE RETENCIÓN) MOTOCICLETA",1,IF(AB8="SERVICIO DE GARAJE EXTRA PESADOS (MÁS DE 12 TN) (DIARIOS)",15,0)))) -> 9 | AE8: =IFERROR(AD8*AC8,0) -> 297 | AF8: =AA8 -> 95747679 | AG8: 46030 | AH8: 95747679 | AI8: MI NEGOCIO EFECTIVO-MI VECINO BANCO PICHINCHA-MI NEGOCIO EFECTIVO | AJ8: =IF(AI8="","",AI8) -> MI NEGOCIO EFECTIVO-MI VECINO BANCO PICHINCHA-MI NEGOCIO EFECTIVO | AK8: =IF(E8="","",E8) -> 2031 | AL8: SGOS. CHASIPANTA XAVIER | AO8: INORME TECNICO PERICIAL DE EVALUO TECNICO MECANICO Y RECONOCIMIENTO DE DAÑOS MATERIALES | AP8: CBOP. FRANCISCO WLADIMIR NASIMBA GUALPA | AQ8: =AG8 -> 46030 | AR8: =AH8 -> 95747679 | AS8: =AJ8 -> MI NEGOCIO EFECTIVO-MI VECINO BANCO PICHINCHA-MI NEGOCIO EFECTIVO
A9: 18 | B9: SANTO DOMINGO | C9: CONTROL 120 | D9: 46034 | E9: 2034 | F9: MAA3069 | G9: VOLSKWAGEN | H9: BUS | I9: 17210 OD 6.5 4X2 TM | J9: ANARANJADO | K9: 2013 | L9: 9F3GH1JGUAXX13056 | M9: J08CTT39521 | N9: 2026011204060520618 | O9: SGOS. PUCHA BYRON | P9: SABANDO ZAMBRANO MARIA FAVIOLA | Q9: ACCIDENTE DE TRANSITO | R9: FISCALIA | S9: N/A | T9: N/A | U9: SGOS. GUERRERO ALBERTO | V9: 46042 | W9: OFICIO No. FPSD-FEAT2-0608-2026-000227-O | X9: MAYR. GALIANO ANDRADE EDISON EDUARDO | Y9: SABANDO ZAMBRANO MARIA FAVIOLA | Z9: 802191395 | AA9: 95961118 | AB9: SERVICIO DE GARAJE PESADOS (DE 3,51 TN HASTA 12 TN) (DIARIOS) | AC9: =(V9-D9)+1 -> 9 | AD9: 9 | AE9: =IFERROR(AD9*AC9,0) -> 81 | AF9: =AA9 -> 95961118 | AG9: 46042 | AH9: 202601204779420 | AI9: BANCO DEL PACIFICO | AJ9: =IF(AI9="","",AI9) -> BANCO DEL PACIFICO | AK9: =IF(E9="","",E9) -> 2034 | AL9: SGOS. GUERRERO ALBERTO | AM9: N/A | AN9: N/A | AO9: INORME TECNICO PERICIAL DE EVALUO TECNICO MECANICO Y RECONOCIMIENTO DE DAÑOS MATERIALES | AP9: CBOS. GUAMAN JEFFERSON | AQ9: =AG9 -> 46042 | AR9: =AH9 -> 202601204779420 | AS9: =AJ9 -> BANCO DEL PACIFICO
A10: 19 | B10: SANTO DOMINGO | C10: CONTROL 120 | D10: 46038 | E10: 2035 | F10: GBN5890 | G10: HINO | H10: VOLQUETA | I10: FM1JLUD AC 8.0 2P 6X4 TM DIESEL | J10: AMARILLO | K10: 2014 | L10: 9F3FM1JLUEXX13122 | M10: J08CTT49883 | N10: 2026011602201191513 | O10: CBOS. CANGO JEFFERSON | P10: CALDERON BRIONES JORGE LUIS | Q10: ACCIDENTE DE TRANSITO | R10: FISCALIA | S10: N/A | T10: N/A | U10: SGOS. CHASIPANTA XAVIER | V10: 46042 | W10: OFICIO No. FPSD-FEAT1-0258-2026-000196-O | X10: MAYR. GALIANO ANDRADE EDISON EDUARDO | Y10: CALDERON BRIONES JORGE LUIS | Z10: 1714373246 | AA10: 95987084 | AB10: SERVICIO DE GARAJE EXTRA PESADOS (MAS DE 12 TN) (DIARIOS) | AC10: =(V10-D10)+1 -> 5 | AD10: 15 | AE10: =IFERROR(AD10*AC10,0) -> 75 | AF10: =AA10 -> 95987084 | AG10: 46042 | AH10: 17162463 | AI10: MI NEGOCIO EFECTIVO | AJ10: =IF(AI10="","",AI10) -> MI NEGOCIO EFECTIVO | AK10: =IF(E10="","",E10) -> 2035 | AL10: SGOS. GUERRERO ALBERTO | AM10: N/A | AN10: N/A | AO10: INORME TECNICO PERICIAL DE EVALUO TECNICO MECANICO Y RECONOCIMIENTO DE DAÑOS MATERIALES | AP10: CBOP. GAVILANEZ LENIN | AQ10: =AG10 -> 46042 | AR10: =AH10 -> 17162463 | AS10: =AJ10 -> MI NEGOCIO EFECTIVO
A11: 30 | B11: SANTO DOMINGO | C11: CONTROL 120 | D11: 46046 | E11: 2036 | F11: JAA3356 | G11: HINO | H11: BUS | I11: AK8JRSA AC 7.7 1P 4X2 TM DIESEL | J11: AZUL | K11: 2025 | L11: JHDAK8JRSLXX17722 | M11: J08EUD33999 | N11: ´2026012408040460418 | O11: SGOP. CHANGO CARLOS | P11: CAIZALUIZA JURADO CARLOS | Q11: ACCIDENTE DE TRANSITO | R11: FISCALIA | U11: SGOS. GUERRERO ALBERTO | V11: 46058 | W11: OF. No. FPSD-FEAT3-0609-2026-00567-O | X11: MAYOR. SUAREZ JACOME JUAN CARLOS | Y11: =P11 -> CAIZALUIZA JURADO CARLOS | Z11: 1701212001 | AA11: 96297335 | AB11: SERVICIO DE GARAJE EXTRA PESADOS (MÁS DE 12 TN) (DIARIOS) | AC11: =(V11-D11)+1 -> 13 | AD11: =IF(AB11="SERVICIO DE GARAJE LIVIANOS (HASTA 3,5 TN A EXCEPCIÓN DE MOTOCICLETAS) (DIARIOS)",3,IF(AB11="SERVICIO DE GARAJE PESADOS (DE 3,51 TN HASTA 12 TN) (DIARIOS)",9,IF(AB11="SERVICIO DE GARAJE (CENTROS DE RETENCIÓN) MOTOCICLETA",1,IF(AB11="SERVICIO DE GARAJE EXTRA PESADOS (MÁS DE 12 TN) (DIARIOS)",15,0)))) -> 15 | AE11: =IFERROR(AD11*AC11,0) -> 195 | AF11: =AA11 -> 96297335 | AG11: 46058 | AH11: 96297335 | AI11: MI NEGOCIO EFECTIVO-MI VECINO BANCO PICHINCHA-MI NEGOCIO EFECTIVO | AJ11: =IF(AI11="","",AI11) -> MI NEGOCIO EFECTIVO-MI VECINO BANCO PICHINCHA-MI NEGOCIO EFECTIVO | AK11: =IF(E11="","",E11) -> 2036 | AL11: SGOS. GUERRERO ALBERTO | AO11: INORME TECNICO PERICIAL DE EVALUO TECNICO MECANICO Y RECONOCIMIENTO DE DAÑOS MATERIALES | AP11: CBOP. FRANCISCO WLADIMIR NASIMBA GUALPA | AQ11: =AG11 -> 46058 | AR11: =AH11 -> 96297335 | AS11: =AJ11 -> MI NEGOCIO EFECTIVO-MI VECINO BANCO PICHINCHA-MI NEGOCIO EFECTIVO
A12: 23 | B12: SANTO DOMINGO | C12: CONTROL 120 | D12: 46049 | E12: 2037 | F12: PAD2356 | G12: SINOTRUK | H12: PLATAFORMA | I12: HOWO T5G ZZ1167K501GE1 AC 6.9 2P 4X2 | J12: BLANCO | K12: 2026 | L12: LZZ1BBKG3TA196146 | M12: 250307806327 | N12: 2026012700585644911 | O12: SGOP. CHANGO CARLOS | P12: QUIROLA VACA LUIS GONZALO | Q12: ACCIDENTE DE TRANSITO | R12: FISCALIA | U12: SGOS. CHASIPANTA XAVIER | V12: 46066 | W12: OF. No. FPSD-FEAT2-0608-2026-000622-O | X12: MAYOR. GALIANO ANDRADE EDISON EDUARDO | Y12: LUIS GONZALO QUIROLA VACA | Z12: 12711739902 | AA12: 96327232 | AB12: SERVICIO DE GARAJE PESADOS (DE 3,51 TN HASTA 12 TN) (DIARIOS) | AC12: =(V12-D12)+1 -> 18 | AD12: 9 | AE12: =IFERROR(AD12*AC12,0) -> 162 | AF12: =AA12 -> 96327232 | AG12: 46066 | AH12: 2026021383227820 | AI12: BANCO DEL PACIFICO | AJ12: =IF(AI12="","",AI12) -> BANCO DEL PACIFICO | AK12: =IF(E12="","",E12) -> 2037 | AL12: POLI. TIPAN KEVIN | AO12: INORME TECNICO PERICIAL DE EVALUO TECNICO MECANICO Y RECONOCIMIENTO DE DAÑOS MATERIALES | AP12: CBOP. REA FREIRE JULIO ERNESTO | AQ12: =AG12 -> 46066 | AR12: =AH12 -> 2026021383227820 | AS12: =AJ12 -> BANCO DEL PACIFICO
A13: 24 | B13: SANTO DOMINGO | C13: CONTROL 120 | D13: 46049 | E13: 2038 | F13: IAK0630 | G13: HINO | H13: CAMIÓN | I13: GH1JMUA | J13: BLANCO | K13: 2009 | L13: JHDGH1JMU9XX13743 | M13: J08CTT34551 | N13: 2026012700585644911 | O13: SGOP. CHANGO CARLOS | P13: COLCHA GUNSHA ERIK ALEXANDER | Q13: ACCIDENTE DE TRANSITO | R13: FISCALIA | U13: SGOS. CHASIPANTA XAVIER | V13: 46077 | W13: OF. No. FPSD-FEAT2-0608-2026-000740-O | X13: MAYOR. SUAREZ JACOME JUAN CARLOS | Y13: =P13 -> COLCHA GUNSHA ERIK ALEXANDER | Z13: 0605787365 | AA13: 96374559 | AB13: SERVICIO DE GARAJE EXTRA PESADOS (MAS DE 12 TN) (DIARIOS) | AC13: =(V13-D13)+1 -> 29 | AD13: 15 | AE13: =IFERROR(AD13*AC13,0) -> 435 | AF13: =AA13 -> 96374559 | AG13: 46077 | AH13: 96374559 | AI13: BANCO DEL PICHINCHA | AJ13: =IF(AI13="","",AI13) -> BANCO DEL PICHINCHA | AK13: =IF(E13="","",E13) -> 2038 | AL13: SGOS. GUERRERO ALBERTO | AO13: INORME TECNICO PERICIAL DE EVALUO TECNICO MECANICO Y RECONOCIMIENTO DE DAÑOS MATERIALES | AP13: CBOP. REA FREIRE JULIO ERNESTO | AQ13: =AG13 -> 46077 | AR13: =AH13 -> 96374559 | AS13: =AJ13 -> BANCO DEL PICHINCHA
A14: 21 | B14: SANTO DOMINGO | C14: CONTROL 120 | D14: 46052 | E14: 2039 | F14: GPX0484 | G14: HINO | H14: CAMIÓN | I14: GH1JMUA | J14: AZUL | K14: 2008 | L14: JHDGH1JMU8XX11914 | M14: J08CTT27435 | N14: 2026013009255363017 | O14: CBOS. CHASI DAVID | P14: CAIZAGUANO CHICAIZA ANGEL DIEGO | Q14: ACCIDENTE DE TRANSITO | R14: FISCALIA | S14: N/A | T14: N/A | U14: SGOS. CHASIPANTA XAVIER | V14: 46101 | W14: OFICIO No. FPSD-FEAT3-0609-2026-001045-O | X14: MAYR. SOLIS MAYORGA PABLO ENRIQUE | Y14: CAIZAGUANO CHICAIZA ANGEL DIEGO | Z14: 0604415398 | AA14: 96697197 | AB14: SERVICIO DE GARAJE EXTRA PESADOS (MAS DE 12 TN) (DIARIOS) | AC14: =(V14-D14)+1 -> 50 | AD14: 15 | AE14: =IFERROR(AD14*AC14,0) -> 750 | AF14: =AA14 -> 96697197 | AG14: 46101 | AH14: 202603209352820 | AI14: BANCO DEL PACIFICO | AJ14: =IF(AI14="","",AI14) -> BANCO DEL PACIFICO | AK14: =IF(E14="","",E14) -> 2039 | AL14: SGOS. GUERRERO ALBERTO | AM14: N/A | AN14: N/A | AO14: INORME TECNICO PERICIAL DE EVALUO TECNICO MECANICO Y RECONOCIMIENTO DE DAÑOS MATERIALES | AP14: CBOP. NASIMBA FRANCISCO | AQ14: =AG14 -> 46101 | AR14: =AH14 -> 202603209352820 | AS14: =AJ14 -> BANCO DEL PACIFICO
A15: 22 | B15: SANTO DOMINGO | C15: CONTROL 120 | D15: 46052 | E15: 2040 | F15: GBO7773 | G15: HINO | H15: FURGON | I15: GH8JM7A-XG3 AC 7.7 2P 4X2 TM DIESEL | J15: BLANCO | K15: 2019 | L15: 9F3GH8JM7KXX10505 | M15: J08EWG10725 | N15: 2.026013e+18 | O15: CBOS. CHASI DAVID | P15: NUÑEZ MORENO JAIME PATRICIO | Q15: ACCIDENTE DE TRANSITO | R15: FISCALIA | S15: N/A | T15: N/A | U15: SGOS. CHASIPANTA XAVIER | V15: 46077 | W15: OFICIO No. FPSD-FEAT3-0609-2026-000735-O | X15: MAYR. SUAREZ JACOME JUAN | Y15: NUÑEZ MORENO JAIME PATRICIO | Z15: 1707104111 | AA15: 96373751 | AB15: SERVICIO DE GARAJE EXTRA PESADOS (MAS DE 12 TN) (DIARIOS) | AC15: =(V15-D15)+1 -> 26 | AD15: 15 | AE15: =IFERROR(AD15*AC15,0) -> 390 | AF15: =AA15 -> 96373751 | AG15: 46077 | AH15: 202602246615320 | AI15: BANCO DEL PACIFICO | AJ15: =IF(AI15="","",AI15) -> BANCO DEL PACIFICO | AK15: =IF(E15="","",E15) -> 2040 | AL15: SGOS. GUERRERO ALBERTO | AM15: N/A | AN15: N/A | AO15: INORME TECNICO PERICIAL DE EVALUO TECNICO MECANICO Y RECONOCIMIENTO DE DAÑOS MATERIALES | AP15: CBOP. DIAZ STALIN | AQ15: =AG15 -> 46077 | AR15: =AH15 -> 202602246615320 | AS15: =AJ15 -> BANCO DEL PACIFICO
A16: 20 | B16: SANTO DOMINGO | C16: CONTROL 120 | D16: 46052 | E16: 2041 | F16: PAB1690 | G16: KENWORTH | H16: TRACTO CAMIÓN | I16: T800 6X4 | J16: NEGRO | K16: 2012 | L16: 1XKDD40X2CR706062 | M16: 79513534 | N16: 2026013009255363017 | O16: CBOS. CHASI DAVID | P16: PERALVO GARCIA MARCO VINIVIO | Q16: ACCIDENTE DE TRANSITO | R16: FISCALIA | S16: N/A | T16: N/A | U16: SGOS. CHASIPANTA XAVIER | V16: 46058 | W16: OFICIO No. FPSD-FEAT3-0609-2026-000574-O | X16: MAYR. SUAREZ JACOME JUAN | Y16: PERALVO GARCIA MARCO VINICIO | Z16: 1716186547 | AA16: 96297232 | AB16: SERVICIO DE GARAJE EXTRA PESADOS (MAS DE 12 TN) (DIARIOS) | AC16: =(V16-D16)+1 -> 7 | AD16: 15 | AE16: =IFERROR(AD16*AC16,0) -> 105 | AF16: =AA16 -> 96297232 | AG16: 46058 | AH16: 17252935 | AI16: SERVIPAGOS | AJ16: =IF(AI16="","",AI16) -> SERVIPAGOS | AK16: =IF(E16="","",E16) -> 2041 | AL16: SGOS. GUERRERO ALBERTO | AM16: N/A | AN16: N/A | AO16: INORME TECNICO PERICIAL DE EVALUO TECNICO MECANICO Y RECONOCIMIENTO DE DAÑOS MATERIALES | AP16: CBOP. SARANGO ROBERTO | AQ16: =AG16 -> 46058 | AR16: =AH16 -> 17252935 | AS16: =AJ16 -> SERVIPAGOS
A17: 25 | B17: SANTO DOMINGO | C17: CONTROL 120 | D17: 46055 | E17: 2042 | F17: PAB3354 | G17: JAC | H17: CANASTILLA | I17: HFC1134KR1 AC 6.7 2P 4X2 TM DIESEL | J17: BLANCO | K17: 2021 | L17: LJ11R2DG9M3200159 | M17: 82068908 | N17: 2026020207283196113 | O17: SGOP. CHANGO CARLOS | P17: MEDINA AROCA LUIS DANIEL | Q17: ACCIDENTE DE TRANSITO | R17: FISCALIA | U17: SGOS. CHASIPANTA XAVIER | V17: 46094 | W17: OF. No. FPSD-FEAT3-0609-2026-000953-O | X17: CPTN. IZA VILLENA RODNEY ESTEBAN | Y17: =P17 -> MEDINA AROCA LUIS DANIEL | Z17: 1717382491 | AB17: SERVICIO DE GARAJE PESADOS (DE 3,51 TN HASTA 12 TN) (DIARIOS) | AC17: =(V17-D17)+1 -> 40 | AD17: 9 | AE17: =IFERROR(AD17*AC17,0) -> 360 | AF17: =AA17 -> 0 | AG17: 46094 | AH17: 96502041-STO-SOL-031301007927594-17305788-7927594 | AI17: BANCO DEL PACIFICO-BANCO DEL PACIFICO | AJ17: =IF(AI17="","",AI17) -> BANCO DEL PACIFICO-BANCO DEL PACIFICO | AK17: =IF(E17="","",E17) -> 2042 | AL17: SGOS. CHASIPANTA XAVIER | AO17: INORME TECNICO PERICIAL DE EVALUO TECNICO MECANICO Y RECONOCIMIENTO DE DAÑOS MATERIALES | AP17: CBOP. GAVILANEZ AZOGUE LENIN | AQ17: =AG17 -> 46094 | AR17: =AH17 -> 96502041-STO-SOL-031301007927594-17305788-7927594 | AS17: =AJ17 -> BANCO DEL PACIFICO-BANCO DEL PACIFICO
A18: 26 | B18: SANTO DOMINGO | C18: CONTROL 120 | D18: 46058 | E18: 2043 | F18: CAE0442 | G18: CHEVROLET | H18: PLATAFORMA | I18: FVR 32P CHASIS CABINADO | J18: BLANCO | K18: 2003 | L18: JALFVR32P33000006 | M18: 6HE1900582 | N18: 2026020503164428108 | O18: SGOP. LOPEZ RICHARD | P18: CAZA MENDEZ JOSE LUIS | Q18: ACCIDENTE DE TRANSITO | R18: FISCALIA | U18: SGOS. GUERRERO ALBEFRTO | V18: 46128 | W18: OF. No. FPSD-FEAT3-0609-2026-001013-O | X18: MAYOR. SUAREZ JACOME JUAN CARLOS | Y18: =P18 -> CAZA MENDEZ JOSE LUIS | Z18: 1721866018 | AA18: 97283471/96689377 | AB18: SERVICIO DE GARAJE PESADOS (DE 3,51 TN HASTA 12 TN) (DIARIOS) | AC18: =(V18-D18)+1 -> 71 | AD18: 9 | AE18: =IFERROR(AD18*AC18,0) -> 639 | AF18: =AA18 -> 97283471/96689377 | AG18: 46128 | AH18: 202604163646507 | AI18: BANCO DEL PACIFICO-BANCO DEL PACIFICO | AJ18: =IF(AI18="","",AI18) -> BANCO DEL PACIFICO-BANCO DEL PACIFICO | AK18: =IF(E18="","",E18) -> 2043 | AL18: POLI. ESCOBAR NIXON | AO18: INORME TECNICO PERICIAL DE EVALUO TECNICO MECANICO Y RECONOCIMIENTO DE DAÑOS MATERIALES | AP18: CBOP. REA FREIRE JULIO ERNESTO | AQ18: =AG18 -> 46128 | AR18: =AH18 -> 202604163646507 | AS18: =AJ18 -> BANCO DEL PACIFICO-BANCO DEL PACIFICO
A19: 27 | B19: SANTO DOMINGO | C19: CONTROL 120 | D19: 46059 | E19: 2044 | F19: POT0362 | G19: NISSAN | H19: FURGON | I19: PKC212MHLB | J19: BLANCO | K19: 2005 | L19: JNBPKC212AM00690 | M19: FE6003685H | N19: 202602060046268501 | O19: SGOP. INCA VICTOR | P19: NELSON ENRIQUE REYES MENA | Q19: ACCIDENTE DE TRANSITO | R19: FISCALIA | U19: SGOS. GUERRERO ALBEFRTO | V19: 46091 | W19: OF. No. FPSD-FEAT2-0608-2026-000872-O | X19: MAYOR SOLIS MAYORGA PABLO | Y19: =P19 -> NELSON ENRIQUE REYES MENA | Z19: 0500450473 | AA19: 96455066 | AB19: SERVICIO DE GARAJE EXTRA PESADOS (MAS DE 12 TN) (DIARIOS) | AC19: =(V19-D19)+1 -> 33 | AD19: 15 | AE19: =IFERROR(AD19*AC19,0) -> 495 | AF19: =AA19 -> 96455066 | AG19: 44995 | AH19: 202603107899120 | AI19: BANCO DEL PACIFICO-BANCO DEL PACIFICO | AJ19: =IF(AI19="","",AI19) -> BANCO DEL PACIFICO-BANCO DEL PACIFICO | AK19: =IF(E19="","",E19) -> 2044 | AL19: SGOS. GUERRERO ALBERTO | AO19: INORME TECNICO PERICIAL DE EVALUO TECNICO MECANICO Y RECONOCIMIENTO DE DAÑOS MATERIALES | AP19: CPTN. RAMIREZ VELASTEGUI SANTIAGO RUBEN | AQ19: =AG19 -> 44995 | AR19: =AH19 -> 202603107899120 | AS19: =AJ19 -> BANCO DEL PACIFICO-BANCO DEL PACIFICO
A20: 33 | B20: SANTO DOMINGO | C20: CONTROL 120 | D20: 46059 | E20: 2045 | F20: GTT9096 | G20: SINOTRUK | H20: CABEZAL | I20: SITRAK C7H ZZ4256V324HC1B AC 12,4 | J20: BLANCO | K20: 2025 | L20: LZZ7CLXB6TC695392 | M20: 250417006807 | N20: ´202602060046268510 | O20: SGOP.MUÑOZ VERA EDWIN JAVIER | P20: ORIENTAL ALIMENTICIA S.A. | Q20: ACCIDENTE DE TRANSITO | R20: FISCALIA | U20: SGOS. GUERRERO ALBERTO | V20: 46106 | W20: OF. No. FPSD-FEAT2-0608-2026-001128-O | X20: MAYOR. SUAREZ JACOME JUAN CARLOS | Y20: BARRAGAN PROAÑO YUDITH NARCISA | Z20: 1206209627 | AA20: 9680021 | AB20: SERVICIO DE GARAJE EXTRA PESADOS (MÁS DE 12 TN) (DIARIOS) | AC20: =(V20-D20)+1 -> 48 | AD20: =IF(AB20="SERVICIO DE GARAJE LIVIANOS (HASTA 3,5 TN A EXCEPCIÓN DE MOTOCICLETAS) (DIARIOS)",3,IF(AB20="SERVICIO DE GARAJE PESADOS (DE 3,51 TN HASTA 12 TN) (DIARIOS)",9,IF(AB20="SERVICIO DE GARAJE (CENTROS DE RETENCIÓN) MOTOCICLETA",1,IF(AB20="SERVICIO DE GARAJE EXTRA PESADOS (MÁS DE 12 TN) (DIARIOS)",15,0)))) -> 15 | AE20: =IFERROR(AD20*AC20,0) -> 720 | AF20: =AA20 -> 9680021 | AG20: 46106 | AH20: 202603255394920 | AI20: BANCO PACIFICO | AJ20: =IF(AI20="","",AI20) -> BANCO PACIFICO | AK20: =IF(E20="","",E20) -> 2045 | AL20: SGOS. GUERRERO ALBERTO | AO20: INORME TECNICO PERICIAL DE EVALUO TECNICO MECANICO Y RECONOCIMIENTO DE DAÑOS MATERIALES | AP20: CPTN. RAMIREZ VELASTEGUI SANTIAGO RUBEN | AQ20: =AG20 -> 46106 | AR20: =AH20 -> 202603255394920 | AS20: =AJ20 -> BANCO PACIFICO
A21: 35 | B21: SANTO DOMINGO | C21: CONTROL 120 | D21: 46064 | E21: 2046 | F21: PAE5673 | G21: JAC | H21: FURGON | I21: CN HFC1063KN 4,5 2P 4X2 TM DIESEL | J21: BLANCO | K21: 2025 | L21: LJ11KRCE8T1901086 | M21: 84635711 | N21: ´2026021110150224117 | O21: SGOP. LOPEZ RICHARD | P21: RODRIGUEZ YUQUI CARMEN AMELIA | Q21: ACCIDENTE DE TRANSITO | R21: FISCALIA | U21: POLI. TIPAN KEVIN | V21: 46086 | W21: OFICIO No. FPSD-FEAT1-0258-2026-001028-O | X21: MAYOR. SUAREZ JACOME JUAN CARLOS | Y21: =P21 -> RODRIGUEZ YUQUI CARMEN AMELIA | Z21: 913220786 | AA21: 96419706 | AB21: SERVICIO DE GARAJE PESADOS (DE 3,51 TN HASTA 12 TN) (DIARIOS) | AC21: =(V21-D21)+1 -> 23 | AD21: =IF(AB21="SERVICIO DE GARAJE LIVIANOS (HASTA 3,5 TN A EXCEPCIÓN DE MOTOCICLETAS) (DIARIOS)",3,IF(AB21="SERVICIO DE GARAJE PESADOS (DE 3,51 TN HASTA 12 TN) (DIARIOS)",9,IF(AB21="SERVICIO DE GARAJE (CENTROS DE RETENCIÓN) MOTOCICLETA",1,IF(AB21="SERVICIO DE GARAJE EXTRA PESADOS (MÁS DE 12 TN) (DIARIOS)",15,0)))) -> 9 | AE21: =IFERROR(AD21*AC21,0) -> 207 | AF21: =AA21 -> 96419706 | AG21: 46085 | AH21: 96419706 | AI21: MI NEGOCIO EFECTIVO BANCO PICHINCHA | AJ21: =IF(AI21="","",AI21) -> MI NEGOCIO EFECTIVO BANCO PICHINCHA | AK21: =IF(E21="","",E21) -> 2046 | AL21: SGOS. GUERRERO ALBERTO | AO21: INORME TECNICO PERICIAL DE EVALUO TECNICO MECANICO Y RECONOCIMIENTO DE DAÑOS MATERIALES | AP21: CBOP. SARANGO ROBERTO | AQ21: =AG21 -> 46085 | AR21: =AH21 -> 96419706 | AS21: =AJ21 -> MI NEGOCIO EFECTIVO BANCO PICHINCHA
A22: 34 | B22: SANTO DOMINGO | C22: CONTROL 120 | D22: 46064 | E22: 2047 | F22: RAA6300 | G22: FOTON | H22: TRACTO CAMIÓN | I22: AUMAN BJ4259 AC 11,8 2P 6X4 TM DIESEL | J22: AMARILLO | K22: 2024 | L22: LVBS6PEBXJT009981 | M22: ISGE343076216065 | N22: ´2026021110150224117 | O22: SGOP. LOPEZ RICHARD | P22: RAMOS ARGUELLO HOLGER ROLANDO | Q22: ACCIDENTE DE TRANSITO | R22: FISCALIA | U22: SGOS. GUERRERO ALBERTO | V22: 46085 | W22: OFICIO No. FPSD-FEAT1-0258-2026-001029-O | X22: MAYOR. SUAREZ JACOME JUAN CARLOS | Y22: =P22 -> RAMOS ARGUELLO HOLGER ROLANDO | Z22: 201455029 | AA22: 96419609 | AB22: SERVICIO DE GARAJE EXTRA PESADOS (MÁS DE 12 TN) (DIARIOS) | AC22: =(V22-D22)+1 -> 22 | AD22: =IF(AB22="SERVICIO DE GARAJE LIVIANOS (HASTA 3,5 TN A EXCEPCIÓN DE MOTOCICLETAS) (DIARIOS)",3,IF(AB22="SERVICIO DE GARAJE PESADOS (DE 3,51 TN HASTA 12 TN) (DIARIOS)",9,IF(AB22="SERVICIO DE GARAJE (CENTROS DE RETENCIÓN) MOTOCICLETA",1,IF(AB22="SERVICIO DE GARAJE EXTRA PESADOS (MÁS DE 12 TN) (DIARIOS)",15,0)))) -> 15 | AE22: =IFERROR(AD22*AC22,0) -> 330 | AF22: =AA22 -> 96419609 | AG22: 46085 | AH22: 96419609 | AI22: BANCO DEL PICHINCHA | AJ22: =IF(AI22="","",AI22) -> BANCO DEL PICHINCHA | AK22: =IF(E22="","",E22) -> 2047 | AL22: SGOS. GUERRERO ALBERTO | AO22: INORME TECNICO PERICIAL DE EVALUO TECNICO MECANICO Y RECONOCIMIENTO DE DAÑOS MATERIALES | AP22: CBOP. SARANGO ROBERTO | AQ22: =AG22 -> 46085 | AR22: =AH22 -> 96419609 | AS22: =AJ22 -> BANCO DEL PICHINCHA
A23: 36 | B23: SANTO DOMINGO | C23: CONTROL 120 | D23: 46074 | E23: 2048 | F23: PCD3784 | G23: HINO | H23: TRACTO CAMIÓN | I23: S81EKVA TM 12,9 2P 6X4 | J23: BLANCO | K23: 2023 | L23: JHDSS1EK701S13321 | M23: E13CTR17378 | N23: ´2026022101231431508 | O23: CBOP. ABATA SANTIAGO | P23: JIMENEZ VACA LEONEL ISRAEL | Q23: ACCIDENTE DE TRANSITO | R23: FISCALIA | U23: SGOS. GUERRERO ALBERTO | V23: 46080 | W23: OF. No. FPSD-FEAT3-0609-2026-00820-O | X23: MAYOR. GALIANO ANDRADE EDISON EDUARDO | Y23: =P23 -> JIMENEZ VACA LEONEL ISRAEL | Z23: 503404246 | AA23: 96398097 | AB23: SERVICIO DE GARAJE EXTRA PESADOS (MÁS DE 12 TN) (DIARIOS) | AC23: =(V23-D23)+1 -> 7 | AD23: =IF(AB23="SERVICIO DE GARAJE LIVIANOS (HASTA 3,5 TN A EXCEPCIÓN DE MOTOCICLETAS) (DIARIOS)",3,IF(AB23="SERVICIO DE GARAJE PESADOS (DE 3,51 TN HASTA 12 TN) (DIARIOS)",9,IF(AB23="SERVICIO DE GARAJE (CENTROS DE RETENCIÓN) MOTOCICLETA",1,IF(AB23="SERVICIO DE GARAJE EXTRA PESADOS (MÁS DE 12 TN) (DIARIOS)",15,0)))) -> 15 | AE23: =IFERROR(AD23*AC23,0) -> 105 | AF23: =AA23 -> 96398097 | AG23: 46080 | AH23: 2542207 | AI23: BANCO DEL PACIFICO | AJ23: =IF(AI23="","",AI23) -> BANCO DEL PACIFICO | AK23: =IF(E23="","",E23) -> 2048 | AL23: POLI. TIPAN KEVIN | AO23: INORME TECNICO PERICIAL DE EVALUO TECNICO MECANICO Y RECONOCIMIENTO DE DAÑOS MATERIALES | AP23: CBOP. ESTALIN PATRICIO DIAZ FUENTES | AQ23: =AG23 -> 46080 | AR23: =AH23 -> 2542207 | AS23: =AJ23 -> BANCO DEL PACIFICO
A24: 38 | B24: SANTO DOMINGO | C24: CONTROL 120 | D24: 46078 | E24: 2050 | F24: RCF0072 | G24: HINO | H24: FURGON | I24: XZ413L-HKMMD | J24: BLANCO | K24: 2025 | L24: JHFUT13H172000027 | M24: N04CTT10139 | N24: ´2026022511524258300 | O24: CBOP. PASPUEL WILSON | P24: DISTRIBUIDORA IMPORTADORA DIPORT | Q24: ACCIDENTE DE TRANSITO | R24: FISCALIA | U24: POLI. TIPAN KEVIN | V24: 46122 | W24: OF. No. PN-SZSDT-JPCTV-DIG-2026-096-O | X24: MAYOR. JARA POZO KERLEY EDUARDO | Y24: GARCES RAMIREZ XIMENA DEL PILAR | Z24: 1706508155 | AA24: 97132574 | AB24: SERVICIO DE GARAJE PESADOS (DE 3,51 TN HASTA 12 TN) (DIARIOS) | AC24: =(V24-D24)+1 -> 45 | AD24: =IF(AB24="SERVICIO DE GARAJE LIVIANOS (HASTA 3,5 TN A EXCEPCIÓN DE MOTOCICLETAS) (DIARIOS)",3,IF(AB24="SERVICIO DE GARAJE PESADOS (DE 3,51 TN HASTA 12 TN) (DIARIOS)",9,IF(AB24="SERVICIO DE GARAJE (CENTROS DE RETENCIÓN) MOTOCICLETA",1,IF(AB24="SERVICIO DE GARAJE EXTRA PESADOS (MÁS DE 12 TN) (DIARIOS)",15,0)))) -> 9 | AE24: =IFERROR(AD24*AC24,0) -> 405 | AF24: =AA24 -> 97132574 | AG24: 46122 | AH24: 202604102635920 | AI24: BANCO DEL PACIFICO | AJ24: =IF(AI24="","",AI24) -> BANCO DEL PACIFICO | AK24: =IF(E24="","",E24) -> 2050 | AL24: SGOS. CHASIPANTA XAVIER | AO24: INORME TECNICO PERICIAL DE EVALUO TECNICO MECANICO Y RECONOCIMIENTO DE DAÑOS MATERIALES | AP24: SGOS. CRUZ CALDERON DANILO FABRICIO | AQ24: =AG24 -> 46122 | AR24: =AH24 -> 202604102635920 | AS24: =AJ24 -> BANCO DEL PACIFICO
A25: 37 | B25: SANTO DOMINGO | C25: CONTROL 120 | D25: 46078 | E25: 2049 | F25: PAB7793 | G25: HINO | H25: FURGON | I25: FM2PR7A-SG3 AC 10,5 2P 6X4 TM DIESEL | J25: BLANCO | K25: 2025 | L25: 9F3FM2PR7MXX10407 | M25: P11CVT21007 | N25: ´2026022607544979807 | O25: SGOP. VIRACOCHA RODOLFO | P25: ALCOCER ZAPATA LUIS GUSTAVO | Q25: ACCIDENTE DE TRANSITO | R25: FISCALIA | U25: POLI. TIPAN KEVIN | V25: 46093 | W25: OF. No. FPSD-FEAT3-0609-2026-000919-O | X25: MAYOR SOLIS MAYORGA PABLO | Y25: =P25 -> ALCOCER ZAPATA LUIS GUSTAVO | Z25: 1710361179 | AA25: 96484775 | AB25: SERVICIO DE GARAJE PESADOS (DE 3,51 TN HASTA 12 TN) (DIARIOS) | AC25: =(V25-D25)+1 -> 16 | AD25: =IF(AB25="SERVICIO DE GARAJE LIVIANOS (HASTA 3,5 TN A EXCEPCIÓN DE MOTOCICLETAS) (DIARIOS)",3,IF(AB25="SERVICIO DE GARAJE PESADOS (DE 3,51 TN HASTA 12 TN) (DIARIOS)",9,IF(AB25="SERVICIO DE GARAJE (CENTROS DE RETENCIÓN) MOTOCICLETA",1,IF(AB25="SERVICIO DE GARAJE EXTRA PESADOS (MÁS DE 12 TN) (DIARIOS)",15,0)))) -> 9 | AE25: =IFERROR(AD25*AC25,0) -> 144 | AF25: =AA25 -> 96484775 | AG25: 46093 | AH25: 96484775 | AI25: MI NEGOCIO EFECTIVO-MI NEGOCIO EFECTIVO | AJ25: =IF(AI25="","",AI25) -> MI NEGOCIO EFECTIVO-MI NEGOCIO EFECTIVO | AK25: =IF(E25="","",E25) -> 2049 | AL25: SGOS. CHASIPANTA XAVIER | AO25: INORME TECNICO PERICIAL DE EVALUO TECNICO MECANICO Y RECONOCIMIENTO DE DAÑOS MATERIALES | AP25: CPTN. RAMIREZ VELASTEGUI SANTIAGO RUBEN | AQ25: =AG25 -> 46093 | AR25: =AH25 -> 96484775 | AS25: =AJ25 -> MI NEGOCIO EFECTIVO-MI NEGOCIO EFECTIVO
A26: 39 | B26: SANTO DOMINGO | C26: CONTROL 120 | D26: 46081 | E26: 2051 | F26: EAA1221 | G26: VOLKSWAGEN | H26: AUTOBUS | I26: 17210 OO 6,5 4X2 TM DIESEL | J26: AZUL | K26: 2023 | L26: 9532F82W3DR313998 | M26: G1T145457 | N26: ´2026022802031976305 | O26: SGOS. CALDERON PABLO | P26: VILATUÑA PINTO LIVIA MARUJA | Q26: ACCIDENTE DE TRANSITO | R26: FISCALIA | U26: POLI. TIPAN KEVIN | V26: 46101 | W26: OF. No. FPSD-FEAT2-0608-2026-0000087-O | X26: MAYOR SOLIS MAYORGA PABLO | Y26: =P26 -> VILATUÑA PINTO LIVIA MARUJA | Z26: 1704123031 | AA26: 96678325 | AB26: SERVICIO DE GARAJE PESADOS (DE 3,51 TN HASTA 12 TN) (DIARIOS) | AC26: =(V26-D26)+1 -> 21 | AD26: =IF(AB26="SERVICIO DE GARAJE LIVIANOS (HASTA 3,5 TN A EXCEPCIÓN DE MOTOCICLETAS) (DIARIOS)",3,IF(AB26="SERVICIO DE GARAJE PESADOS (DE 3,51 TN HASTA 12 TN) (DIARIOS)",9,IF(AB26="SERVICIO DE GARAJE (CENTROS DE RETENCIÓN) MOTOCICLETA",1,IF(AB26="SERVICIO DE GARAJE EXTRA PESADOS (MÁS DE 12 TN) (DIARIOS)",15,0)))) -> 9 | AE26: =IFERROR(AD26*AC26,0) -> 189 | AF26: =AA26 -> 96678325 | AG26: 46101 | AH26: 202603206199420 | AI26: BANCO DEL PACIFICO | AJ26: =IF(AI26="","",AI26) -> BANCO DEL PACIFICO | AK26: =IF(E26="","",E26) -> 2051 | AL26: SGOS. GUERRERO ALBERTO | AO26: INORME TECNICO PERICIAL DE EVALUO TECNICO MECANICO Y RECONOCIMIENTO DE DAÑOS MATERIALES | AP26: CBOP. ESTALIN PATRICIO DIAZ FUENTES | AQ26: =AG26 -> 46101 | AR26: =AH26 -> 202603206199420 | AS26: =AJ26 -> BANCO DEL PACIFICO
A27: 40 | B27: SANTO DOMINGO | C27: CONTROL 120 | D27: 46087 | E27: 2052 | F27: XAA1180 | G27: KENWORTH | H27: TRACTO CAMIÓN | I27: T800 ESPECIAL EDITION AERODYNAME | J27: ANARANJADO | K27: 2022 | L27: 3WKDD40XXEF718448 | M27: 79657554 | N27: ´2026030607392661603 | O27: CBOS. CUÑEZ GUALOMOTO BRYAN OSWALDO | P27: CHACON MOLINA PABLO ALFREDO | Q27: ACCIDENTE DE TRANSITO | R27: FISCALIA | U27: CBOP. BRAULIO ACUÑA | V27: 46093 | W27: OF. No. FPSD-FEAT1-3009-2026-000034-O | X27: MAYOR SOLIS MAYORGA PABLO | Y27: =P27 -> CHACON MOLINA PABLO ALFREDO | Z27: ´0502119522 | AA27: 96482810 | AB27: SERVICIO DE GARAJE EXTRA PESADOS (MÁS DE 12 TN) (DIARIOS) | AC27: =(V27-D27)+1 -> 7 | AD27: =IF(AB27="SERVICIO DE GARAJE LIVIANOS (HASTA 3,5 TN A EXCEPCIÓN DE MOTOCICLETAS) (DIARIOS)",3,IF(AB27="SERVICIO DE GARAJE PESADOS (DE 3,51 TN HASTA 12 TN) (DIARIOS)",9,IF(AB27="SERVICIO DE GARAJE (CENTROS DE RETENCIÓN) MOTOCICLETA",1,IF(AB27="SERVICIO DE GARAJE EXTRA PESADOS (MÁS DE 12 TN) (DIARIOS)",15,0)))) -> 15 | AE27: =IFERROR(AD27*AC27,0) -> 105 | AF27: =AA27 -> 96482810 | AG27: 46093 | AH27: 202603122529220 | AI27: BANCO DEL PACIFICO | AJ27: =IF(AI27="","",AI27) -> BANCO DEL PACIFICO | AK27: =IF(E27="","",E27) -> 2052 | AL27: SGOS. CHASIPANTA XAVIER | AO27: INORME TECNICO PERICIAL DE EVALUO TECNICO MECANICO Y RECONOCIMIENTO DE DAÑOS MATERIALES | AP27: AGENTE GAROFALO ROBERTO | AQ27: =AG27 -> 46093 | AR27: =AH27 -> 202603122529220 | AS27: =AJ27 -> BANCO DEL PACIFICO
A28: 41 | B28: SANTO DOMINGO | C28: CONTROL 120 | D28: 46091 | E28: 2053 | F28: JAA1725 | G28: HINO | H28: BUS | I28: AK8JRSA AC 7.7 1P 4X2 TM DIESEL | J28: AZUL | K28: 2022 | L28: JHDAK8JRSEXX12015 | M28: J08EUD19818 | N28: ´2026031001195636511 | O28: SGOP.MUÑOZ VERA EDWIN JAVIER | P28: MONTERO PINOS EDUARDO ANGEL | Q28: ACCIDENTE DE TRANSITO | R28: FISCALIA | U28: SGOS. GUERRERO ALBERTO | V28: 46093 | W28: OF. No. 1157-2026-FGE-UFSDT | X28: CPTN. IZA VILLENA RODNEY ESTEBAN | Y28: =P28 -> MONTERO PINOS EDUARDO ANGEL | Z28: 1500421878 | AA28: 96499759 | AB28: SERVICIO DE GARAJE EXTRA PESADOS (MÁS DE 12 TN) (DIARIOS) | AC28: =(V28-D28)+1 -> 3 | AD28: =IF(AB28="SERVICIO DE GARAJE LIVIANOS (HASTA 3,5 TN A EXCEPCIÓN DE MOTOCICLETAS) (DIARIOS)",3,IF(AB28="SERVICIO DE GARAJE PESADOS (DE 3,51 TN HASTA 12 TN) (DIARIOS)",9,IF(AB28="SERVICIO DE GARAJE (CENTROS DE RETENCIÓN) MOTOCICLETA",1,IF(AB28="SERVICIO DE GARAJE EXTRA PESADOS (MÁS DE 12 TN) (DIARIOS)",15,0)))) -> 15 | AE28: =IFERROR(AD28*AC28,0) -> 45 | AF28: =AA28 -> 96499759 | AG28: 46093 | AH28: 96499759 | AI28: MI NEGOCIO EFECTIVO-MI VECINO BANCO PICHINCHA-MI NEGOCIO EFECTIVO | AJ28: =IF(AI28="","",AI28) -> MI NEGOCIO EFECTIVO-MI VECINO BANCO PICHINCHA-MI NEGOCIO EFECTIVO | AK28: =IF(E28="","",E28) -> 2053 | AL28: SGOS. CHASIPANTA XAVIER | AO28: INORME TECNICO PERICIAL DE EVALUO TECNICO MECANICO Y RECONOCIMIENTO DE DAÑOS MATERIALES | AP28: CBOP. LENIN ORLANDO GAVILANEZ AZOGUE | AQ28: =AG28 -> 46093 | AR28: =AH28 -> 96499759 | AS28: =AJ28 -> MI NEGOCIO EFECTIVO-MI VECINO BANCO PICHINCHA-MI NEGOCIO EFECTIVO
A29: 42 | B29: SANTO DOMINGO | C29: CONTROL 120 | D29: 46094 | E29: 2054 | F29: IBA1861 | G29: CHEVROLET | H29: CAMIÓN | I29: FVR 23P CHASIS CABINADO | J29: BLANCO | K29: 2026 | L29: JALFVR23P970000093 | M29: 6SD1416579 | N29: ´202603130919564104 | O29: SGOP. LOPEZ RICHARD | P29: CHINGAL ZUÑIGA DALY VANESSA | Q29: ACCIDENTE DE TRANSITO | R29: FISCALIA | U29: SGOS. CHASIPANTA XAVIER | V29: 46100 | W29: OF. No. FPSD-FEAT3-0609-2026-0001037-O | X29: MAYOR SOLIS MAYORGA PABLO | Y29: =P29 -> CHINGAL ZUÑIGA DALY VANESSA | Z29: 1758756249 | AA29: 96656269 | AB29: SERVICIO DE GARAJE PESADOS (DE 3,51 TN HASTA 12 TN) (DIARIOS) | AC29: =(V29-D29)+1 -> 7 | AD29: =IF(AB29="SERVICIO DE GARAJE LIVIANOS (HASTA 3,5 TN A EXCEPCIÓN DE MOTOCICLETAS) (DIARIOS)",3,IF(AB29="SERVICIO DE GARAJE PESADOS (DE 3,51 TN HASTA 12 TN) (DIARIOS)",9,IF(AB29="SERVICIO DE GARAJE (CENTROS DE RETENCIÓN) MOTOCICLETA",1,IF(AB29="SERVICIO DE GARAJE EXTRA PESADOS (MÁS DE 12 TN) (DIARIOS)",15,0)))) -> 9 | AE29: =IFERROR(AD29*AC29,0) -> 63 | AF29: =AA29 -> 96656269 | AG29: 46100 | AH29: 202603199742220 | AI29: BANCO DEL PACIFICO | AJ29: =IF(AI29="","",AI29) -> BANCO DEL PACIFICO | AK29: =IF(E29="","",E29) -> 2054 | AL29: SGOS. GUERRERO ALBERTO | AO29: INORME TECNICO PERICIAL DE EVALUO TECNICO MECANICO Y RECONOCIMIENTO DE DAÑOS MATERIALES | AP29: CBOS. GUAMAN FREIRE JEFFERSON GUILLERMO | AQ29: =AG29 -> 46100 | AR29: =AH29 -> 202603199742220 | AS29: =AJ29 -> BANCO DEL PACIFICO
A30: 43 | B30: SANTO DOMINGO | C30: CONTROL 120 | D30: 46094 | E30: 2055 | F30: PAE1001 | G30: KENWORTH | H30: TRACTO CAMIÓN | I30: T880 AC 15,0 2P 6X4 | J30: AZUL | K30: 2023 | L30: 3WKZD40X4PF203924 | M30: 80414982 | N30: ´202603130919564104 | O30: SGOP. LOPEZ RICHARD | P30: PERALVO GARCIA MARCO VINIVIO | Q30: ACCIDENTE DE TRANSITO | R30: FISCALIA | U30: SGOS. GUERRERO ALBERTO | V30: 46100 | W30: OF. No. FPSD-FEAT3-0609-2026-0001038-O | X30: MAYOR SOLIS MAYORGA PABLO | Y30: =P30 -> PERALVO GARCIA MARCO VINIVIO | Z30: 1716186547 | AA30: 96668135 | AB30: SERVICIO DE GARAJE EXTRA PESADOS (MÁS DE 12 TN) (DIARIOS) | AC30: =(V30-D30)+1 -> 7 | AD30: =IF(AB30="SERVICIO DE GARAJE LIVIANOS (HASTA 3,5 TN A EXCEPCIÓN DE MOTOCICLETAS) (DIARIOS)",3,IF(AB30="SERVICIO DE GARAJE PESADOS (DE 3,51 TN HASTA 12 TN) (DIARIOS)",9,IF(AB30="SERVICIO DE GARAJE (CENTROS DE RETENCIÓN) MOTOCICLETA",1,IF(AB30="SERVICIO DE GARAJE EXTRA PESADOS (MÁS DE 12 TN) (DIARIOS)",15,0)))) -> 15 | AE30: =IFERROR(AD30*AC30,0) -> 105 | AF30: =AA30 -> 96668135 | AG30: 46100 | AH30: NO LEGIBLE | AI30: NO LEGIBLE | AJ30: =IF(AI30="","",AI30) -> NO LEGIBLE | AK30: =IF(E30="","",E30) -> 2055 | AL30: SGOS. GUERRERO ALBERTO | AO30: INORME TECNICO PERICIAL DE EVALUO TECNICO MECANICO Y RECONOCIMIENTO DE DAÑOS MATERIALES | AP30: CBOS. GUAMAN FREIRE JEFFERSON GUILLERMO | AQ30: =AG30 -> 46100 | AR30: =AH30 -> NO LEGIBLE | AS30: =AJ30 -> NO LEGIBLE
A31: 44 | B31: SANTO DOMINGO | C31: CONTROL 120 | D31: 46095 | E31: 2056 | F31: JAA3530 | G31: HINO | H31: BUS | I31: AK8JRSA AC 7.7 1P 4X2 TM DIESEL | J31: PLATEADO | K31: 2025 | L31: JHDAK8JRSPXX19028 | M31: J08EUD36562 | N31: ´202603140924020503 | O31: SGOS. PINZON DIEGO | P31: HARO OÑATE MARTHA CECILIA | Q31: ACCIDENTE DE TRANSITO | R31: FISCALIA | U31: SGOS. CHASIPANTA XAVIER | V31: 46101 | W31: OF. No. FPSD-FEAT2-0608-2026-0001094-O | X31: MAYOR SOLIS MAYORGA PABLO | Y31: =P31 -> HARO OÑATE MARTHA CECILIA | Z31: ´0601972102 | AA31: 96698265 | AB31: SERVICIO DE GARAJE EXTRA PESADOS (MÁS DE 12 TN) (DIARIOS) | AC31: =(V31-D31)+1 -> 7 | AD31: =IF(AB31="SERVICIO DE GARAJE LIVIANOS (HASTA 3,5 TN A EXCEPCIÓN DE MOTOCICLETAS) (DIARIOS)",3,IF(AB31="SERVICIO DE GARAJE PESADOS (DE 3,51 TN HASTA 12 TN) (DIARIOS)",9,IF(AB31="SERVICIO DE GARAJE (CENTROS DE RETENCIÓN) MOTOCICLETA",1,IF(AB31="SERVICIO DE GARAJE EXTRA PESADOS (MÁS DE 12 TN) (DIARIOS)",15,0)))) -> 15 | AE31: =IFERROR(AD31*AC31,0) -> 105 | AF31: =AA31 -> 96698265 | AG31: 46101 | AH31: 96698265 | AI31: MI NEGOCIO EFECTIVO-MI VECINO BANCO PICHINCHA-MI NEGOCIO EFECTIVO | AJ31: =IF(AI31="","",AI31) -> MI NEGOCIO EFECTIVO-MI VECINO BANCO PICHINCHA-MI NEGOCIO EFECTIVO | AK31: =IF(E31="","",E31) -> 2056 | AL31: SGOS. GUERRERO ALBERTO | AO31: INORME TECNICO PERICIAL DE EVALUO TECNICO MECANICO Y RECONOCIMIENTO DE DAÑOS MATERIALES | AP31: CBOP. LENIN ORLANDO GAVILANEZ AZOGUE | AQ31: =AG31 -> 46101 | AR31: =AH31 -> 96698265 | AS31: =AJ31 -> MI NEGOCIO EFECTIVO-MI VECINO BANCO PICHINCHA-MI NEGOCIO EFECTIVO
A32: 29 | B32: SANTO DOMINGO | C32: CONTROL 120 | D32: 46098 | E32: 2057 | F32: QAA3010 | G32: MERCEDEZ BENZ | H32: CABEZAL | I32: ACTROS 2645 AC | J32: PLOMO | K32: 2024 | L32: W1T954414R0732992 | M32: 460972U1147075 | N32: 20260311709433770701 | O32: SGOP. LOPEZ RICHARD | P32: AGILA LALANGUI OLGA ISABEL | Q32: ACCIDENTE DE TRANSITO | R32: FISCALIA | U32: SGOS. GUERRERO ALBERTO | V32: 46108 | W32: OF. No. FPSD-FEAT2-0608-2026-001221-O | X32: MAYOR. JARA POZO KERLEY EDUARDO | Y32: =P32 -> AGILA LALANGUI OLGA ISABEL | Z32: 1718853326 | AA32: 96859148 | AB32: SERVICIO DE GARAJE EXTRA PESADOS (MAS DE 12 TN) (DIARIOS) | AC32: =(V32-D32)+1 -> 11 | AD32: 15 | AE32: =IFERROR(AD32*AC32,0) -> 165 | AF32: =AA32 -> 96859148 | AG32: 46108 | AH32: 021238 | AI32: BANCO PICHINCHA - MI NEGOCIO EFECTIVO | AJ32: =IF(AI32="","",AI32) -> BANCO PICHINCHA - MI NEGOCIO EFECTIVO | AK32: =IF(E32="","",E32) -> 2057 | AL32: SGOS. CHASIPANTA XAVIER | AO32: INORME TECNICO PERICIAL DE EVALUO TECNICO MECANICO Y RECONOCIMIENTO DE DAÑOS MATERIALES | AP32: CBOP. SARANGO ROBERTO | AQ32: =AG32 -> 46108 | AR32: =AH32 -> 021238 | AS32: =AJ32 -> BANCO PICHINCHA - MI NEGOCIO EFECTIVO
A33: 45 | B33: SANTO DOMINGO | C33: CONTROL 120 | D33: 46098 | E33: 2060 | F33: XCB0016 | G33: HINO | H33: CAMIÓN | I33: FC4JJUA | J33: BLANCO | K33: 2023 | L33: JHDFC4JJU6XX13474 | M33: J05CTF17658 | N33: ´2026031810551959409 | O33: POLI. CACOANGO ALEX | P33: MURILLO VELAZQUEZ STALIN LEONEL | Q33: ACCIDENTE DE TRANSITO | R33: FISCALIA | U33: SGOS. GUERRERO ALBERTO | V33: 46113 | W33: OF. No. FPSD-FEAT3-0609-2026-0001127-O | X33: MAYOR SOLIS MAYORGA PABLO | Y33: =P33 -> MURILLO VELAZQUEZ STALIN LEONEL | Z33: 2350595589 | AA33: 96937060 | AB33: SERVICIO DE GARAJE PESADOS (DE 3,51 TN HASTA 12 TN) (DIARIOS) | AC33: =(V33-D33)+1 -> 16 | AD33: =IF(AB33="SERVICIO DE GARAJE LIVIANOS (HASTA 3,5 TN A EXCEPCIÓN DE MOTOCICLETAS) (DIARIOS)",3,IF(AB33="SERVICIO DE GARAJE PESADOS (DE 3,51 TN HASTA 12 TN) (DIARIOS)",9,IF(AB33="SERVICIO DE GARAJE (CENTROS DE RETENCIÓN) MOTOCICLETA",1,IF(AB33="SERVICIO DE GARAJE EXTRA PESADOS (MÁS DE 12 TN) (DIARIOS)",15,0)))) -> 9 | AE33: =IFERROR(AD33*AC33,0) -> 144 | AF33: =AA33 -> 96937060 | AG33: 46113 | AH33: 3263695 | AI33: BANCO DEL PACIFICO | AJ33: =IF(AI33="","",AI33) -> BANCO DEL PACIFICO | AK33: =IF(E33="","",E33) -> 2060 | AL33: SGOS. CHASIPANTA XAVIER | AO33: INORME TECNICO PERICIAL DE EVALUO TECNICO MECANICO Y RECONOCIMIENTO DE DAÑOS MATERIALES | AP33: CBOS. GUAMAN JEFFERSON | AQ33: =AG33 -> 46113 | AR33: =AH33 -> 3263695 | AS33: =AJ33 -> BANCO DEL PACIFICO
A34: 16 | B34: SANTO DOMINGO | C34: CONTROL 120 | D34: 46103 | E34: 2058 | F34: CAA1101 | G34: INTERNATIONAL | H34: TRACTO CAMIÓN | I34: PROSTAR 6X4 | J34: ROJO | K34: 2012 | L34: 3HSDJAPT8CN121141 | M34: 79529239 | N34: 2026032310204179007 | O34: CBOS. CHASI DAVID | P34: TAPIA LOPEZ EDGAR FERNANDO | Q34: ACCIDENTE DE TRANSITO | R34: FISCALIA | S34: N/A | T34: N/A | U34: SGOS. GUERRERO ALBERTO | V34: 46113 | W34: OFICIO No. FPSD-FEAT3-0609-2026-001130-O | X34: MAYR. SOLIS MAYORGA PABLO ENRIQUE | Y34: TAPIA LOPEZ EDGAR FERNANDO | Z34: 0502060635 | AA34: 96956780 | AB34: SERVICIO DE GARAJE EXTRA PESADOS (MAS DE 12 TN) (DIARIOS) | AC34: =(V34-D34)+1 -> 11 | AD34: 15 | AE34: =IFERROR(AD34*AC34,0) -> 165 | AF34: =AA34 -> 96956780 | AG34: 46113 | AH34: 17427986 | AI34: MI NEGOCIO EFECTIVO | AJ34: =IF(AI34="","",AI34) -> MI NEGOCIO EFECTIVO | AK34: =IF(E34="","",E34) -> 2058 | AL34: SGOS. CHASIPANTA XAVIER | AM34: N/A | AN34: N/A | AO34: INORME TECNICO PERICIAL DE EVALUO TECNICO MECANICO Y RECONOCIMIENTO DE DAÑOS MATERIALES | AP34: CBOP. NASIMBA FABRICIO | AQ34: =AG34 -> 46113 | AR34: =AH34 -> 17427986 | AS34: =AJ34 -> MI NEGOCIO EFECTIVO
A35: 14 | B35: SANTO DOMINGO | C35: CONTROL 120 | D35: 46103 | E35: 2059 | F35: CBL0337 | G35: CHEVROLET | H35: FURGON | I35: FTR 32M | J35: ROJO | K35: 2003 | L35: JALFTR32M37000024 | M35: 6HE1900984 | N35: 202603237112163205 | O35: POLI. SANCHEZ JOSE | P35: CHANGOLUISA VENEGAS OSCAR ROLANDO | Q35: ART. 160 | R35: JUZGADO | S35: N/A | T35: N/A | U35: SGOS. GUERRERO ALBERTO | V35: 46104 | W35: N/A | X35: N/A | Y35: CHANGOLUISA VENEGAS OSACAR RO,ANDO | Z35: 1713838694 | AA35: 96734834 | AB35: SERVICIO DE GARAJE PESADOS (DE 3,51 TN HASTA 12 TN) (DIARIOS) | AC35: =(V35-D35)+1 -> 2 | AD35: 9 | AE35: =IFERROR(AD35*AC35,0) -> 18 | AF35: =AA35 -> 96734834 | AG35: 46104 | AH35: 202603238895620 | AI35: BANCO DEL PACIFICO | AJ35: =IF(AI35="","",AI35) -> BANCO DEL PACIFICO | AK35: =IF(E35="","",E35) -> 2059 | AL35: SGOS. GUERRERO ALBERTO | AM35: N/A | AN35: N/A | AO35: N/A | AP35: N/A | AQ35: =AG35 -> 46104 | AR35: =AH35 -> 202603238895620 | AS35: =AJ35 -> BANCO DEL PACIFICO
A36: 2 | B36: SANTO DOMINGO | C36: CONTROL 120 | D36: 46108 | E36: 2061 | F36: CAE0061 | G36: HINO | I36: FF1JPTZ | J36: BLANCO | K36: 2002 | L36: JHDFF1JPT2XX10220 | M36: J08CTT11016 | N36: 2026032703225956301 | O36: SGOS. BRAVO HENRY | P36: LARA PAREDES PABLO WILMER | Q36: ACCIDENTE DE TRANSITO | R36: FISCALIA | S36: N/A | T36: N/A | U36: SGOS. CHASIPANTA XAVIER | AC36: =(V36-D36)+1 -> -46107 | AD36: =IF(AB36="SERVICIO DE GARAJE LIVIANOS (HASTA 3,5 TN A EXCEPCIÓN DE MOTOCICLETAS) (DIARIOS)",3,IF(AB36="SERVICIO DE GARAJE PESADOS (DE 3,51 TN HASTA 12 TN) (DIARIOS)",9,IF(AB36="SERVICIO DE GARAJE (CENTROS DE RETENCIÓN) MOTOCICLETA",1,IF(AB36="SERVICIO DE GARAJE EXTRA PESADOS (MÁS DE 12 TN) (DIARIOS)",15,0)))) -> 0 | AE36: =IFERROR(AD36*AC36,0) -> 0 | AF36: =AA36 -> 0 | AJ36: =IF(AI36="","",AI36) | AK36: =IF(E36="","",E36) -> 2061 | AM36: N/A | AN36: N/A | AQ36: =AG36 -> 0 | AR36: =AH36 -> 0 | AS36: =AJ36
A37: 3 | B37: SANTO DOMINGO | C37: CONTROL 120 | D37: 46109 | E37: 2062 | F37: TBB2616 | G37: JAC | H37: CAMIÓN | I37: HFC1035KD | J37: BLANCO | K37: 2010 | L37: LJ11KBACXA6000780 | M37: 94011328 | N37: 2026032809402780510 | O37: CBOP. GARCIA MANUEL | P37: VALERA VILLAVICENCIO CHISTIAN | Q37: ACCIDENTE DE TRANSITO | R37: FISCALIA | S37: N/A | T37: N/A | U37: POLI. TIPAN KEVIN | V37: 46156 | W37: OF. No. FPSD-FEAT3-0609-2026-001632-O | X37: MAYR. SUAREZ JACOME JUAN CARLOS | Y37: VALERA VILLAVICENCIO CHRISTIAN EMMANUEL | Z37: 1726674011 | AB37: SERVICIO DE GARAJE LIVIANOS (HASTA 3,5 TN A EXCEPCIÓN DE MOTOCICLETAS) (DIARIOS) | AC37: =(V37-D37)+1 -> 48 | AD37: =IF(AB37="SERVICIO DE GARAJE LIVIANOS (HASTA 3,5 TN A EXCEPCIÓN DE MOTOCICLETAS) (DIARIOS)",3,IF(AB37="SERVICIO DE GARAJE PESADOS (DE 3,51 TN HASTA 12 TN) (DIARIOS)",9,IF(AB37="SERVICIO DE GARAJE (CENTROS DE RETENCIÓN) MOTOCICLETA",1,IF(AB37="SERVICIO DE GARAJE EXTRA PESADOS (MÁS DE 12 TN) (DIARIOS)",15,0)))) -> 3 | AE37: =IFERROR(AD37*AC37,0) -> 144 | AF37: =AA37 -> 0 | AG37: 46156 | AH37: 98092628 | AI37: SERVIPAGOS AGENTE | AJ37: =IF(AI37="","",AI37) -> SERVIPAGOS AGENTE | AK37: =IF(E37="","",E37) -> 2062 | AL37: POLI. ESCOBAR NIXON | AM37: N/A | AN37: N/A | AQ37: =AG37 -> 46156 | AR37: =AH37 -> 98092628 | AS37: =AJ37 -> SERVIPAGOS AGENTE
A38: 15 | B38: SANTO DOMINGO | C38: CONTROL 120 | D38: 46109 | E38: 2063 | F38: JEI1029 | G38: HINO | H38: VOLQUETA | I38: GH1JGUD | J38: AMARILLO | K38: 2010 | L38: 9F3GH1JGUAXX13056 | M38: J08CTT39521 | N38: 2026032809402780510 | O38: CBOP. GARCIA MANUEL | P38: GAD STO. DOMINGO | Q38: ACCIDENTE TRANSITO | R38: FISCALIA | S38: N/A | T38: N/A | U38: POLI. TIPAN KEVIN | V38: 46121 | W38: OFICIO No. FPSD-FEAT3-0609-2026-001190-O | X38: MAYR. SUAREZ JACOME JUAN | Y38: ROJAS PEDRERA ADRIANA ALEXANDRA | Z38: 1719428508 | AA38: 97116636 | AB38: SERVICIO DE GARAJE EXTRA PESADOS (MAS DE 12 TN) (DIARIOS) | AC38: =(V38-D38)+1 -> 13 | AD38: 15 | AE38: =IFERROR(AD38*AC38,0) -> 195 | AF38: =AA38 -> 97116636 | AG38: 46121 | AH38: 17473943 | AI38: MI NEGOCIO EFECTIVO | AJ38: =IF(AI38="","",AI38) -> MI NEGOCIO EFECTIVO | AK38: =IF(E38="","",E38) -> 2063 | AL38: POLI. ESCOBAR NIXON | AM38: N/A | AN38: N/A | AO38: INORME TECNICO PERICIAL DE EVALUO TECNICO MECANICO Y RECONOCIMIENTO DE DAÑOS MATERIALES | AP38: SGOS. CRUZ DANILO | AQ38: =AG38 -> 46121 | AR38: =AH38 -> 17473943 | AS38: =AJ38 -> MI NEGOCIO EFECTIVO
A39: 4 | B39: SANTO DOMINGO | C39: CONTROL 120 | D39: 46116 | E39: 2064 | F39: GBQ1564 | G39: HINO | I39: FC9JJ7A-BBAHFAA AC 5.1 2P 4X2 TM DIESEL | J39: BLANCO | K39: 2025 | L39: 9F3FC9JJ7SXX12899 | M39: J05EVC14384 | O39: SGOS. ANDAGOYA GERMAN | P39: TORRES NIETO JORGE ABRAHAM | Q39: ART. 160 | R39: N/A | S39: N/A | T39: N/A | U39: POLI. HURTADO KLEVER | AC39: =(V39-D39)+1 -> -46115 | AD39: =IF(AB39="SERVICIO DE GARAJE LIVIANOS (HASTA 3,5 TN A EXCEPCIÓN DE MOTOCICLETAS) (DIARIOS)",3,IF(AB39="SERVICIO DE GARAJE PESADOS (DE 3,51 TN HASTA 12 TN) (DIARIOS)",9,IF(AB39="SERVICIO DE GARAJE (CENTROS DE RETENCIÓN) MOTOCICLETA",1,IF(AB39="SERVICIO DE GARAJE EXTRA PESADOS (MÁS DE 12 TN) (DIARIOS)",15,0)))) -> 0 | AE39: =IFERROR(AD39*AC39,0) -> 0 | AF39: =AA39 -> 0 | AJ39: =IF(AI39="","",AI39) | AK39: =IF(E39="","",E39) -> 2064 | AM39: N/A | AN39: N/A | AQ39: =AG39 -> 0 | AR39: =AH39 -> 0 | AS39: =AJ39
A40: 28 | B40: SANTO DOMINGO | C40: CONTROL 120 | D40: 46117 | E40: 2065 | F40: TAT0311 | G40: HINO | H40: AUTOBUS | I40: GD1JPTZ | J40: AZUL | K40: 2005 | L40: JHDGD1JPT5XX11460 | M40: J08CTW13590 | N40: 2026040610455152911 | O40: POLI. MENDOZA LEONEL | P40: GUANOQUIZA VALIENTE MILTON PATRICIO | Q40: ART. 386 INCISO 3 #1 | R40: N/A | U40: POLI. LUNA XAVIER | V40: 46137 | W40: OF. No PN-SZSDT-JPCTSV-DIG-2026-0108-O | X40: CBOS. MONAR GUAÑA GENESIS ELIZABETH | Y40: =P40 -> GUANOQUIZA VALIENTE MILTON PATRICIO | Z40: 0502919780 | AA40: 97524839/97528534 | AB40: SERVICIO DE GARAJE EXTRA PESADOS (MAS DE 12 TN) (DIARIOS) | AC40: =(V40-D40)+1 -> 21 | AD40: 15 | AE40: =IFERROR(AD40*AC40,0) -> 315 | AF40: =AA40 -> 97524839/97528534 | AG40: 24/04/2026 25/04/2026 | AH40: 202604243613480 202604253816371 | AI40: BANCO GUAYAQUIL | AJ40: =IF(AI40="","",AI40) -> BANCO GUAYAQUIL | AK40: =IF(E40="","",E40) -> 2065 | AL40: SGOS. CHASIPANTA XAVIER | AO40: N/A | AP40: N/A | AQ40: 24/04/2026 25/04/2026 | AR40: =AH40 -> 202604243613480 202604253816371 | AS40: =AJ40 -> BANCO GUAYAQUIL
A41: 17 | B41: SANTO DOMINGO | C41: CONTROL 120 | D41: 46122 | E41: 2066 | F41: PAA8922 | G41: CHEVROLET | H41: CAMIÓN | I41: FRR 90L 5 2 2P 4X2 TM DIESEL | J41: BLANCO | K41: 2019 | L41: JALFRR90LK7000011 | M41: 4HK1682249 | N41: 202604100449574102 | O41: CBOS. MERIZALDE NICK | P41: PAEZ MIÑIZ JORGE REINALDO | Q41: ACCIDENTE DE TRANSITO | R41: FISCALIA | S41: N/A | T41: N/A | U41: SGOS. CHASIPANTA XAVIER | V41: 46134 | W41: OFICIO No. FPSD-FEAT3-0609-2026-001325-O | X41: MAYR. SUAREZ JACOME JUAN | Y41: PAEZ MUÑIZ JORGE REINALDO | Z41: 1723853600 | AA41: 97420031 | AB41: SERVICIO DE GARAJE PESADOS (DE 3,51 TN HASTA 12 TN) (DIARIOS) | AC41: =(V41-D41)+1 -> 13 | AD41: 9 | AE41: =IFERROR(AD41*AC41,0) -> 117 | AF41: =AA41 -> 97420031 | AG41: 46134 | AH41: 17555437 | AI41: MI NEGOCIO EFECTIVO | AJ41: =IF(AI41="","",AI41) -> MI NEGOCIO EFECTIVO | AK41: =IF(E41="","",E41) -> 2066 | AL41: POLI. ESCOBAR NIXON | AM41: N/A | AN41: N/A | AO41: INORME TECNICO PERICIAL DE EVALUO TECNICO MECANICO Y RECONOCIMIENTO DE DAÑOS MATERIALES | AP41: CBOS. GUAMAN JEFFERSON | AQ41: =AG41 -> 46134 | AR41: =AH41 -> 17555437 | AS41: =AJ41 -> MI NEGOCIO EFECTIVO
...

Sheet INVENTARIO CAJA 1
A1: COMANDO GENERAL
A2: INVENTARIO DOCUMENTAL DE TRANSFERENCIA PRIMARIA
A3: SECCIÓN: | C3: Jefatura Operativa de Control del Tránsito y Seguridad Vial
A4: SUB SECCIÓN: | C4: Patio de retención vehicular
F5: FECHAS EXTREMAS | K5: UBICACIÓN TOPOGRÁFICA
A6: SERIE /SUBSERIE DOCUMENTAL | B6: N° CAJA | C6: N° DE EXPEDIENTE | D6: N° DE TOMO | E6: DESCRIPCIÓN | F6: APERTURA | G6: CIERRE | H6: N° FOJAS | I6: DESTINO FINAL | J6: SOPORTE | K6: ZONA | L6: ESTANTERÍA | M6: BANDEJA | N6: OBSERVACIONES | O6: PLACA (CLAVE DE VÍNCULO)
A7: Retenciones Vehiculares | B7: 1 | C7: 0002_2026 | D7: 1/1 | E7: =IF($O7="","",IFERROR("Parte policial Nro. "&SUBSTITUTE(INDEX(VEHICULOS!$N:$N,MATCH($O7,VEHICULOS!$F:$F,0)),"´","")&", Hoja de Ingreso y Salida Nro. "&TEXT(INDEX(VEHICULOS!$E:$E,MATCH($O7,VEHICULOS!$F:$F,0)),"0000000")&", entregado al señor "&INDEX(VEHICULOS!$P:$P,MATCH($O7,VEHICULOS!$F:$F,0))&", con cédula "&INDEX(VEHICULOS!$Z:$Z,MATCH($O7,VEHICULOS!$F:$F,0))&" del Vehiculo Tipo "&INDEX(VEHICULOS!$H:$H,MATCH($O7,VEHICULOS!$F:$F,0))&" marca "&INDEX(VEHICULOS!$G:$G,MATCH($O7,VEHICULOS!$F:$F,0))&", color "&INDEX(VEHICULOS!$J:$J,MATCH($O7,VEHICULOS!$F:$F,0))&" con placas "&$O7&", por "&INDEX(VEHICULOS!$Q:$Q,MATCH($O7,VEHICULOS!$F:$F,0))&".","REVISAR: placa no encontrada en VEHICULOS")) -> Parte policial Nro. 202512071018484501, Hoja de Ingreso y Salida Nro. 0002031, entregado al señor ONTANEDA YEPEZ JORGE ANIBAL, con cédula 1711325496 del Vehiculo Tipo CISTERNA marca FORD, color BLANCO con placas PQF0838, por ACCIDENTE DE TRANSITO. | F7: =IF($O7="","",IFERROR(INDEX(VEHICULOS!$D:$D,MATCH($O7,VEHICULOS!$F:$F,0)),"")) -> 45998 | G7: =IF($O7="","",IFERROR(INDEX(VEHICULOS!$V:$V,MATCH($O7,VEHICULOS!$F:$F,0)),"")) -> 46030 | H7: 18 | I7: Eliminación | J7: Fisico | O7: PQF0838
A8: Retenciones Vehiculares | B8: 1 | C8: 0003_2026 | D8: 1/1 | E8: =IF($O8="","",IFERROR("Parte policial Nro. "&SUBSTITUTE(INDEX(VEHICULOS!$N:$N,MATCH($O8,VEHICULOS!$F:$F,0)),"´","")&", Hoja de Ingreso y Salida Nro. "&TEXT(INDEX(VEHICULOS!$E:$E,MATCH($O8,VEHICULOS!$F:$F,0)),"0000000")&", entregado al señor "&INDEX(VEHICULOS!$P:$P,MATCH($O8,VEHICULOS!$F:$F,0))&", con cédula "&INDEX(VEHICULOS!$Z:$Z,MATCH($O8,VEHICULOS!$F:$F,0))&" del Vehiculo Tipo "&INDEX(VEHICULOS!$H:$H,MATCH($O8,VEHICULOS!$F:$F,0))&" marca "&INDEX(VEHICULOS!$G:$G,MATCH($O8,VEHICULOS!$F:$F,0))&", color "&INDEX(VEHICULOS!$J:$J,MATCH($O8,VEHICULOS!$F:$F,0))&" con placas "&$O8&", por "&INDEX(VEHICULOS!$Q:$Q,MATCH($O8,VEHICULOS!$F:$F,0))&".","REVISAR: placa no encontrada en VEHICULOS")) -> Parte policial Nro. 2026011204060520618, Hoja de Ingreso y Salida Nro. 0002034, entregado al señor SABANDO ZAMBRANO MARIA FAVIOLA, con cédula 802191395 del Vehiculo Tipo BUS marca VOLSKWAGEN, color ANARANJADO con placas MAA3069, por ACCIDENTE DE TRANSITO. | F8: =IF($O8="","",IFERROR(INDEX(VEHICULOS!$D:$D,MATCH($O8,VEHICULOS!$F:$F,0)),"")) -> 46034 | G8: =IF($O8="","",IFERROR(INDEX(VEHICULOS!$V:$V,MATCH($O8,VEHICULOS!$F:$F,0)),"")) -> 46042 | H8: 21 | I8: Eliminación | J8: Fisico | O8: MAA3069
A9: Retenciones Vehiculares | B9: 1 | C9: 0004_2026 | D9: 1/1 | E9: =IF($O9="","",IFERROR("Parte policial Nro. "&SUBSTITUTE(INDEX(VEHICULOS!$N:$N,MATCH($O9,VEHICULOS!$F:$F,0)),"´","")&", Hoja de Ingreso y Salida Nro. "&TEXT(INDEX(VEHICULOS!$E:$E,MATCH($O9,VEHICULOS!$F:$F,0)),"0000000")&", entregado al señor "&INDEX(VEHICULOS!$P:$P,MATCH($O9,VEHICULOS!$F:$F,0))&", con cédula "&INDEX(VEHICULOS!$Z:$Z,MATCH($O9,VEHICULOS!$F:$F,0))&" del Vehiculo Tipo "&INDEX(VEHICULOS!$H:$H,MATCH($O9,VEHICULOS!$F:$F,0))&" marca "&INDEX(VEHICULOS!$G:$G,MATCH($O9,VEHICULOS!$F:$F,0))&", color "&INDEX(VEHICULOS!$J:$J,MATCH($O9,VEHICULOS!$F:$F,0))&" con placas "&$O9&", por "&INDEX(VEHICULOS!$Q:$Q,MATCH($O9,VEHICULOS!$F:$F,0))&".","REVISAR: placa no encontrada en VEHICULOS")) -> Parte policial Nro. 2026011602201191513, Hoja de Ingreso y Salida Nro. 0002035, entregado al señor CALDERON BRIONES JORGE LUIS, con cédula 1714373246 del Vehiculo Tipo VOLQUETA marca HINO, color AMARILLO con placas GBN5890, por ACCIDENTE DE TRANSITO. | F9: =IF($O9="","",IFERROR(INDEX(VEHICULOS!$D:$D,MATCH($O9,VEHICULOS!$F:$F,0)),"")) -> 46038 | G9: =IF($O9="","",IFERROR(INDEX(VEHICULOS!$V:$V,MATCH($O9,VEHICULOS!$F:$F,0)),"")) -> 46042 | H9: 21 | I9: Eliminación | J9: Fisico | O9: GBN5890
A10: Retenciones Vehiculares | B10: 1 | C10: 0005_2026 | D10: 1/1 | E10: =IF($O10="","",IFERROR("Parte policial Nro. "&SUBSTITUTE(INDEX(VEHICULOS!$N:$N,MATCH($O10,VEHICULOS!$F:$F,0)),"´","")&", Hoja de Ingreso y Salida Nro. "&TEXT(INDEX(VEHICULOS!$E:$E,MATCH($O10,VEHICULOS!$F:$F,0)),"0000000")&", entregado al señor "&INDEX(VEHICULOS!$P:$P,MATCH($O10,VEHICULOS!$F:$F,0))&", con cédula "&INDEX(VEHICULOS!$Z:$Z,MATCH($O10,VEHICULOS!$F:$F,0))&" del Vehiculo Tipo "&INDEX(VEHICULOS!$H:$H,MATCH($O10,VEHICULOS!$F:$F,0))&" marca "&INDEX(VEHICULOS!$G:$G,MATCH($O10,VEHICULOS!$F:$F,0))&", color "&INDEX(VEHICULOS!$J:$J,MATCH($O10,VEHICULOS!$F:$F,0))&" con placas "&$O10&", por "&INDEX(VEHICULOS!$Q:$Q,MATCH($O10,VEHICULOS!$F:$F,0))&".","REVISAR: placa no encontrada en VEHICULOS")) -> Parte policial Nro. 2026012408040460418, Hoja de Ingreso y Salida Nro. 0002036, entregado al señor CAIZALUIZA JURADO CARLOS, con cédula 1701212001 del Vehiculo Tipo BUS marca HINO, color AZUL con placas JAA3356, por ACCIDENTE DE TRANSITO. | F10: =IF($O10="","",IFERROR(INDEX(VEHICULOS!$D:$D,MATCH($O10,VEHICULOS!$F:$F,0)),"")) -> 46046 | G10: =IF($O10="","",IFERROR(INDEX(VEHICULOS!$V:$V,MATCH($O10,VEHICULOS!$F:$F,0)),"")) -> 46058 | H10: 17 | I10: Eliminación | J10: Fisico | O10: JAA3356
A11: Retenciones Vehiculares | B11: 1 | C11: 0006_2026 | D11: 1/1 | E11: =IF($O11="","",IFERROR("Parte policial Nro. "&SUBSTITUTE(INDEX(VEHICULOS!$N:$N,MATCH($O11,VEHICULOS!$F:$F,0)),"´","")&", Hoja de Ingreso y Salida Nro. "&TEXT(INDEX(VEHICULOS!$E:$E,MATCH($O11,VEHICULOS!$F:$F,0)),"0000000")&", entregado al señor "&INDEX(VEHICULOS!$P:$P,MATCH($O11,VEHICULOS!$F:$F,0))&", con cédula "&INDEX(VEHICULOS!$Z:$Z,MATCH($O11,VEHICULOS!$F:$F,0))&" del Vehiculo Tipo "&INDEX(VEHICULOS!$H:$H,MATCH($O11,VEHICULOS!$F:$F,0))&" marca "&INDEX(VEHICULOS!$G:$G,MATCH($O11,VEHICULOS!$F:$F,0))&", color "&INDEX(VEHICULOS!$J:$J,MATCH($O11,VEHICULOS!$F:$F,0))&" con placas "&$O11&", por "&INDEX(VEHICULOS!$Q:$Q,MATCH($O11,VEHICULOS!$F:$F,0))&".","REVISAR: placa no encontrada en VEHICULOS")) -> Parte policial Nro. 2026012700585644911, Hoja de Ingreso y Salida Nro. 0002037, entregado al señor QUIROLA VACA LUIS GONZALO, con cédula 12711739902 del Vehiculo Tipo PLATAFORMA marca SINOTRUK, color BLANCO con placas PAD2356, por ACCIDENTE DE TRANSITO. | F11: =IF($O11="","",IFERROR(INDEX(VEHICULOS!$D:$D,MATCH($O11,VEHICULOS!$F:$F,0)),"")) -> 46049 | G11: =IF($O11="","",IFERROR(INDEX(VEHICULOS!$V:$V,MATCH($O11,VEHICULOS!$F:$F,0)),"")) -> 46066 | H11: 20 | I11: Eliminación | J11: Fisico | O11: PAD2356
A12: Retenciones Vehiculares | B12: 1 | C12: 0007_2026 | D12: 1/1 | E12: =IF($O12="","",IFERROR("Parte policial Nro. "&SUBSTITUTE(INDEX(VEHICULOS!$N:$N,MATCH($O12,VEHICULOS!$F:$F,0)),"´","")&", Hoja de Ingreso y Salida Nro. "&TEXT(INDEX(VEHICULOS!$E:$E,MATCH($O12,VEHICULOS!$F:$F,0)),"0000000")&", entregado al señor "&INDEX(VEHICULOS!$P:$P,MATCH($O12,VEHICULOS!$F:$F,0))&", con cédula "&INDEX(VEHICULOS!$Z:$Z,MATCH($O12,VEHICULOS!$F:$F,0))&" del Vehiculo Tipo "&INDEX(VEHICULOS!$H:$H,MATCH($O12,VEHICULOS!$F:$F,0))&" marca "&INDEX(VEHICULOS!$G:$G,MATCH($O12,VEHICULOS!$F:$F,0))&", color "&INDEX(VEHICULOS!$J:$J,MATCH($O12,VEHICULOS!$F:$F,0))&" con placas "&$O12&", por "&INDEX(VEHICULOS!$Q:$Q,MATCH($O12,VEHICULOS!$F:$F,0))&".","REVISAR: placa no encontrada en VEHICULOS")) -> Parte policial Nro. 2026012700585644911, Hoja de Ingreso y Salida Nro. 0002038, entregado al señor COLCHA GUNSHA ERIK ALEXANDER, con cédula 0605787365 del Vehiculo Tipo CAMIÓN marca HINO, color BLANCO con placas IAK0630, por ACCIDENTE DE TRANSITO. | F12: =IF($O12="","",IFERROR(INDEX(VEHICULOS!$D:$D,MATCH($O12,VEHICULOS!$F:$F,0)),"")) -> 46049 | G12: =IF($O12="","",IFERROR(INDEX(VEHICULOS!$V:$V,MATCH($O12,VEHICULOS!$F:$F,0)),"")) -> 46077 | H12: 17 | I12: Eliminación | J12: Fisico | O12: IAK0630
A13: Retenciones Vehiculares | B13: 1 | C13: 0008_2026 | D13: 1/1 | E13: =IF($O13="","",IFERROR("Parte policial Nro. "&SUBSTITUTE(INDEX(VEHICULOS!$N:$N,MATCH($O13,VEHICULOS!$F:$F,0)),"´","")&", Hoja de Ingreso y Salida Nro. "&TEXT(INDEX(VEHICULOS!$E:$E,MATCH($O13,VEHICULOS!$F:$F,0)),"0000000")&", entregado al señor "&INDEX(VEHICULOS!$P:$P,MATCH($O13,VEHICULOS!$F:$F,0))&", con cédula "&INDEX(VEHICULOS!$Z:$Z,MATCH($O13,VEHICULOS!$F:$F,0))&" del Vehiculo Tipo "&INDEX(VEHICULOS!$H:$H,MATCH($O13,VEHICULOS!$F:$F,0))&" marca "&INDEX(VEHICULOS!$G:$G,MATCH($O13,VEHICULOS!$F:$F,0))&", color "&INDEX(VEHICULOS!$J:$J,MATCH($O13,VEHICULOS!$F:$F,0))&" con placas "&$O13&", por "&INDEX(VEHICULOS!$Q:$Q,MATCH($O13,VEHICULOS!$F:$F,0))&".","REVISAR: placa no encontrada en VEHICULOS")) -> Parte policial Nro. 2026013009255360000, Hoja de Ingreso y Salida Nro. 0002040, entregado al señor NUÑEZ MORENO JAIME PATRICIO, con cédula 1707104111 del Vehiculo Tipo FURGON marca HINO, color BLANCO con placas GBO7773, por ACCIDENTE DE TRANSITO. | F13: =IF($O13="","",IFERROR(INDEX(VEHICULOS!$D:$D,MATCH($O13,VEHICULOS!$F:$F,0)),"")) -> 46052 | G13: =IF($O13="","",IFERROR(INDEX(VEHICULOS!$V:$V,MATCH($O13,VEHICULOS!$F:$F,0)),"")) -> 46077 | H13: 15 | I13: Eliminación | J13: Fisico | O13: GBO7773
A14: Retenciones Vehiculares | B14: 1 | C14: 0009_2026 | D14: 1/1 | E14: =IF($O14="","",IFERROR("Parte policial Nro. "&SUBSTITUTE(INDEX(VEHICULOS!$N:$N,MATCH($O14,VEHICULOS!$F:$F,0)),"´","")&", Hoja de Ingreso y Salida Nro. "&TEXT(INDEX(VEHICULOS!$E:$E,MATCH($O14,VEHICULOS!$F:$F,0)),"0000000")&", entregado al señor "&INDEX(VEHICULOS!$P:$P,MATCH($O14,VEHICULOS!$F:$F,0))&", con cédula "&INDEX(VEHICULOS!$Z:$Z,MATCH($O14,VEHICULOS!$F:$F,0))&" del Vehiculo Tipo "&INDEX(VEHICULOS!$H:$H,MATCH($O14,VEHICULOS!$F:$F,0))&" marca "&INDEX(VEHICULOS!$G:$G,MATCH($O14,VEHICULOS!$F:$F,0))&", color "&INDEX(VEHICULOS!$J:$J,MATCH($O14,VEHICULOS!$F:$F,0))&" con placas "&$O14&", por "&INDEX(VEHICULOS!$Q:$Q,MATCH($O14,VEHICULOS!$F:$F,0))&".","REVISAR: placa no encontrada en VEHICULOS")) -> Parte policial Nro. 2026013009255363017, Hoja de Ingreso y Salida Nro. 0002041, entregado al señor PERALVO GARCIA MARCO VINIVIO, con cédula 1716186547 del Vehiculo Tipo TRACTO CAMIÓN marca KENWORTH, color NEGRO con placas PAB1690, por ACCIDENTE DE TRANSITO. | F14: =IF($O14="","",IFERROR(INDEX(VEHICULOS!$D:$D,MATCH($O14,VEHICULOS!$F:$F,0)),"")) -> 46052 | G14: =IF($O14="","",IFERROR(INDEX(VEHICULOS!$V:$V,MATCH($O14,VEHICULOS!$F:$F,0)),"")) -> 46058 | H14: 17 | I14: Eliminación | J14: Fisico | O14: PAB1690
A15: Retenciones Vehiculares | B15: 1 | C15: 0010_2026 | D15: 1/1 | E15: =IF($O15="","",IFERROR("Parte policial Nro. "&SUBSTITUTE(INDEX(VEHICULOS!$N:$N,MATCH($O15,VEHICULOS!$F:$F,0)),"´","")&", Hoja de Ingreso y Salida Nro. "&TEXT(INDEX(VEHICULOS!$E:$E,MATCH($O15,VEHICULOS!$F:$F,0)),"0000000")&", entregado al señor "&INDEX(VEHICULOS!$P:$P,MATCH($O15,VEHICULOS!$F:$F,0))&", con cédula "&INDEX(VEHICULOS!$Z:$Z,MATCH($O15,VEHICULOS!$F:$F,0))&" del Vehiculo Tipo "&INDEX(VEHICULOS!$H:$H,MATCH($O15,VEHICULOS!$F:$F,0))&" marca "&INDEX(VEHICULOS!$G:$G,MATCH($O15,VEHICULOS!$F:$F,0))&", color "&INDEX(VEHICULOS!$J:$J,MATCH($O15,VEHICULOS!$F:$F,0))&" con placas "&$O15&", por "&INDEX(VEHICULOS!$Q:$Q,MATCH($O15,VEHICULOS!$F:$F,0))&".","REVISAR: placa no encontrada en VEHICULOS")) -> Parte policial Nro. 2026020207283196113, Hoja de Ingreso y Salida Nro. 0002042, entregado al señor MEDINA AROCA LUIS DANIEL, con cédula 1717382491 del Vehiculo Tipo CANASTILLA marca JAC, color BLANCO con placas PAB3354, por ACCIDENTE DE TRANSITO. | F15: =IF($O15="","",IFERROR(INDEX(VEHICULOS!$D:$D,MATCH($O15,VEHICULOS!$F:$F,0)),"")) -> 46055 | G15: =IF($O15="","",IFERROR(INDEX(VEHICULOS!$V:$V,MATCH($O15,VEHICULOS!$F:$F,0)),"")) -> 46094 | H15: 13 | I15: Eliminación | J15: Fisico | O15: PAB3354
A16: Retenciones Vehiculares | B16: 1 | C16: 0011_2026 | D16: 1/1 | E16: =IF($O16="","",IFERROR("Parte policial Nro. "&SUBSTITUTE(INDEX(VEHICULOS!$N:$N,MATCH($O16,VEHICULOS!$F:$F,0)),"´","")&", Hoja de Ingreso y Salida Nro. "&TEXT(INDEX(VEHICULOS!$E:$E,MATCH($O16,VEHICULOS!$F:$F,0)),"0000000")&", entregado al señor "&INDEX(VEHICULOS!$P:$P,MATCH($O16,VEHICULOS!$F:$F,0))&", con cédula "&INDEX(VEHICULOS!$Z:$Z,MATCH($O16,VEHICULOS!$F:$F,0))&" del Vehiculo Tipo "&INDEX(VEHICULOS!$H:$H,MATCH($O16,VEHICULOS!$F:$F,0))&" marca "&INDEX(VEHICULOS!$G:$G,MATCH($O16,VEHICULOS!$F:$F,0))&", color "&INDEX(VEHICULOS!$J:$J,MATCH($O16,VEHICULOS!$F:$F,0))&" con placas "&$O16&", por "&INDEX(VEHICULOS!$Q:$Q,MATCH($O16,VEHICULOS!$F:$F,0))&".","REVISAR: placa no encontrada en VEHICULOS")) -> Parte policial Nro. 202602060046268501, Hoja de Ingreso y Salida Nro. 0002044, entregado al señor NELSON ENRIQUE REYES MENA, con cédula 0500450473 del Vehiculo Tipo FURGON marca NISSAN, color BLANCO con placas POT0362, por ACCIDENTE DE TRANSITO. | F16: =IF($O16="","",IFERROR(INDEX(VEHICULOS!$D:$D,MATCH($O16,VEHICULOS!$F:$F,0)),"")) -> 46059 | G16: =IF($O16="","",IFERROR(INDEX(VEHICULOS!$V:$V,MATCH($O16,VEHICULOS!$F:$F,0)),"")) -> 46091 | H16: 20 | I16: Eliminación | J16: Fisico | O16: POT0362
